[2019-09-26 06:46:47] ERROR Internal Server Error: /articles/comment/4
Traceback (most recent call last):
  File "/home/ilkemirnurullah/.local/share/virtualenvs/Blog-0am4vL-A/lib/python3.5/site-packages/django/db/backends/utils.py", line 85, in _execute
    return self.cursor.execute(sql, params)
psycopg2.errors.NotNullViolation: null value in column "comment_id" violates not-null constraint
DETAIL:  Failing row contains (Yorum, 2019-09-26 03:46:47.901588+00, 4, 2, null).


The above exception was the direct cause of the following exception:

Traceback (most recent call last):
  File "/home/ilkemirnurullah/.local/share/virtualenvs/Blog-0am4vL-A/lib/python3.5/site-packages/django/core/handlers/exception.py", line 34, in inner
    response = get_response(request)
  File "/home/ilkemirnurullah/.local/share/virtualenvs/Blog-0am4vL-A/lib/python3.5/site-packages/django/core/handlers/base.py", line 126, in _get_response
    response = self.process_exception_by_middleware(e, request)
  File "/home/ilkemirnurullah/.local/share/virtualenvs/Blog-0am4vL-A/lib/python3.5/site-packages/django/core/handlers/base.py", line 124, in _get_response
    response = wrapped_callback(request, *callback_args, **callback_kwargs)
  File "/home/ilkemirnurullah/.local/share/virtualenvs/Blog-0am4vL-A/lib/python3.5/site-packages/django/contrib/auth/decorators.py", line 21, in _wrapped_view
    return view_func(request, *args, **kwargs)
  File "/home/ilkemirnurullah/Blog/article/views.py", line 109, in addComment
    newComment.save()
  File "/home/ilkemirnurullah/.local/share/virtualenvs/Blog-0am4vL-A/lib/python3.5/site-packages/django/db/models/base.py", line 718, in save
    force_update=force_update, update_fields=update_fields)
  File "/home/ilkemirnurullah/.local/share/virtualenvs/Blog-0am4vL-A/lib/python3.5/site-packages/django/db/models/base.py", line 748, in save_base
    updated = self._save_table(raw, cls, force_insert, force_update, using, update_fields)
  File "/home/ilkemirnurullah/.local/share/virtualenvs/Blog-0am4vL-A/lib/python3.5/site-packages/django/db/models/base.py", line 831, in _save_table
    result = self._do_insert(cls._base_manager, using, fields, update_pk, raw)
  File "/home/ilkemirnurullah/.local/share/virtualenvs/Blog-0am4vL-A/lib/python3.5/site-packages/django/db/models/base.py", line 869, in _do_insert
    using=using, raw=raw)
  File "/home/ilkemirnurullah/.local/share/virtualenvs/Blog-0am4vL-A/lib/python3.5/site-packages/django/db/models/manager.py", line 82, in manager_method
    return getattr(self.get_queryset(), name)(*args, **kwargs)
  File "/home/ilkemirnurullah/.local/share/virtualenvs/Blog-0am4vL-A/lib/python3.5/site-packages/django/db/models/query.py", line 1136, in _insert
    return query.get_compiler(using=using).execute_sql(return_id)
  File "/home/ilkemirnurullah/.local/share/virtualenvs/Blog-0am4vL-A/lib/python3.5/site-packages/django/db/models/sql/compiler.py", line 1289, in execute_sql
    cursor.execute(sql, params)
  File "/home/ilkemirnurullah/.local/share/virtualenvs/Blog-0am4vL-A/lib/python3.5/site-packages/django/db/backends/utils.py", line 68, in execute
    return self._execute_with_wrappers(sql, params, many=False, executor=self._execute)
  File "/home/ilkemirnurullah/.local/share/virtualenvs/Blog-0am4vL-A/lib/python3.5/site-packages/django/db/backends/utils.py", line 77, in _execute_with_wrappers
    return executor(sql, params, many, context)
  File "/home/ilkemirnurullah/.local/share/virtualenvs/Blog-0am4vL-A/lib/python3.5/site-packages/django/db/backends/utils.py", line 85, in _execute
    return self.cursor.execute(sql, params)
  File "/home/ilkemirnurullah/.local/share/virtualenvs/Blog-0am4vL-A/lib/python3.5/site-packages/django/db/utils.py", line 89, in __exit__
    raise dj_exc_value.with_traceback(traceback) from exc_value
  File "/home/ilkemirnurullah/.local/share/virtualenvs/Blog-0am4vL-A/lib/python3.5/site-packages/django/db/backends/utils.py", line 85, in _execute
    return self.cursor.execute(sql, params)
django.db.utils.IntegrityError: null value in column "comment_id" violates not-null constraint
DETAIL:  Failing row contains (Yorum, 2019-09-26 03:46:47.901588+00, 4, 2, null).

[2019-09-26 06:46:56] ERROR Internal Server Error: /articles/comment/4
Traceback (most recent call last):
  File "/home/ilkemirnurullah/.local/share/virtualenvs/Blog-0am4vL-A/lib/python3.5/site-packages/django/db/backends/utils.py", line 85, in _execute
    return self.cursor.execute(sql, params)
psycopg2.errors.NotNullViolation: null value in column "comment_id" violates not-null constraint
DETAIL:  Failing row contains (Yorum, 2019-09-26 03:46:56.319503+00, 4, 2, null).


The above exception was the direct cause of the following exception:

Traceback (most recent call last):
  File "/home/ilkemirnurullah/.local/share/virtualenvs/Blog-0am4vL-A/lib/python3.5/site-packages/django/core/handlers/exception.py", line 34, in inner
    response = get_response(request)
  File "/home/ilkemirnurullah/.local/share/virtualenvs/Blog-0am4vL-A/lib/python3.5/site-packages/django/core/handlers/base.py", line 126, in _get_response
    response = self.process_exception_by_middleware(e, request)
  File "/home/ilkemirnurullah/.local/share/virtualenvs/Blog-0am4vL-A/lib/python3.5/site-packages/django/core/handlers/base.py", line 124, in _get_response
    response = wrapped_callback(request, *callback_args, **callback_kwargs)
  File "/home/ilkemirnurullah/.local/share/virtualenvs/Blog-0am4vL-A/lib/python3.5/site-packages/django/contrib/auth/decorators.py", line 21, in _wrapped_view
    return view_func(request, *args, **kwargs)
  File "/home/ilkemirnurullah/Blog/article/views.py", line 109, in addComment
    newComment.save()
  File "/home/ilkemirnurullah/.local/share/virtualenvs/Blog-0am4vL-A/lib/python3.5/site-packages/django/db/models/base.py", line 718, in save
    force_update=force_update, update_fields=update_fields)
  File "/home/ilkemirnurullah/.local/share/virtualenvs/Blog-0am4vL-A/lib/python3.5/site-packages/django/db/models/base.py", line 748, in save_base
    updated = self._save_table(raw, cls, force_insert, force_update, using, update_fields)
  File "/home/ilkemirnurullah/.local/share/virtualenvs/Blog-0am4vL-A/lib/python3.5/site-packages/django/db/models/base.py", line 831, in _save_table
    result = self._do_insert(cls._base_manager, using, fields, update_pk, raw)
  File "/home/ilkemirnurullah/.local/share/virtualenvs/Blog-0am4vL-A/lib/python3.5/site-packages/django/db/models/base.py", line 869, in _do_insert
    using=using, raw=raw)
  File "/home/ilkemirnurullah/.local/share/virtualenvs/Blog-0am4vL-A/lib/python3.5/site-packages/django/db/models/manager.py", line 82, in manager_method
    return getattr(self.get_queryset(), name)(*args, **kwargs)
  File "/home/ilkemirnurullah/.local/share/virtualenvs/Blog-0am4vL-A/lib/python3.5/site-packages/django/db/models/query.py", line 1136, in _insert
    return query.get_compiler(using=using).execute_sql(return_id)
  File "/home/ilkemirnurullah/.local/share/virtualenvs/Blog-0am4vL-A/lib/python3.5/site-packages/django/db/models/sql/compiler.py", line 1289, in execute_sql
    cursor.execute(sql, params)
  File "/home/ilkemirnurullah/.local/share/virtualenvs/Blog-0am4vL-A/lib/python3.5/site-packages/django/db/backends/utils.py", line 68, in execute
    return self._execute_with_wrappers(sql, params, many=False, executor=self._execute)
  File "/home/ilkemirnurullah/.local/share/virtualenvs/Blog-0am4vL-A/lib/python3.5/site-packages/django/db/backends/utils.py", line 77, in _execute_with_wrappers
    return executor(sql, params, many, context)
  File "/home/ilkemirnurullah/.local/share/virtualenvs/Blog-0am4vL-A/lib/python3.5/site-packages/django/db/backends/utils.py", line 85, in _execute
    return self.cursor.execute(sql, params)
  File "/home/ilkemirnurullah/.local/share/virtualenvs/Blog-0am4vL-A/lib/python3.5/site-packages/django/db/utils.py", line 89, in __exit__
    raise dj_exc_value.with_traceback(traceback) from exc_value
  File "/home/ilkemirnurullah/.local/share/virtualenvs/Blog-0am4vL-A/lib/python3.5/site-packages/django/db/backends/utils.py", line 85, in _execute
    return self.cursor.execute(sql, params)
django.db.utils.IntegrityError: null value in column "comment_id" violates not-null constraint
DETAIL:  Failing row contains (Yorum, 2019-09-26 03:46:56.319503+00, 4, 2, null).

[2019-09-26 06:47:34] ERROR Internal Server Error: /articles/comment/4
Traceback (most recent call last):
  File "/home/ilkemirnurullah/.local/share/virtualenvs/Blog-0am4vL-A/lib/python3.5/site-packages/django/db/backends/utils.py", line 85, in _execute
    return self.cursor.execute(sql, params)
psycopg2.errors.NotNullViolation: null value in column "comment_id" violates not-null constraint
DETAIL:  Failing row contains (Yorum, 2019-09-26 03:47:34.290823+00, 4, 2, null).


The above exception was the direct cause of the following exception:

Traceback (most recent call last):
  File "/home/ilkemirnurullah/.local/share/virtualenvs/Blog-0am4vL-A/lib/python3.5/site-packages/django/core/handlers/exception.py", line 34, in inner
    response = get_response(request)
  File "/home/ilkemirnurullah/.local/share/virtualenvs/Blog-0am4vL-A/lib/python3.5/site-packages/django/core/handlers/base.py", line 126, in _get_response
    response = self.process_exception_by_middleware(e, request)
  File "/home/ilkemirnurullah/.local/share/virtualenvs/Blog-0am4vL-A/lib/python3.5/site-packages/django/core/handlers/base.py", line 124, in _get_response
    response = wrapped_callback(request, *callback_args, **callback_kwargs)
  File "/home/ilkemirnurullah/.local/share/virtualenvs/Blog-0am4vL-A/lib/python3.5/site-packages/django/contrib/auth/decorators.py", line 21, in _wrapped_view
    return view_func(request, *args, **kwargs)
  File "/home/ilkemirnurullah/Blog/article/views.py", line 109, in addComment
    newComment.save()
  File "/home/ilkemirnurullah/.local/share/virtualenvs/Blog-0am4vL-A/lib/python3.5/site-packages/django/db/models/base.py", line 718, in save
    force_update=force_update, update_fields=update_fields)
  File "/home/ilkemirnurullah/.local/share/virtualenvs/Blog-0am4vL-A/lib/python3.5/site-packages/django/db/models/base.py", line 748, in save_base
    updated = self._save_table(raw, cls, force_insert, force_update, using, update_fields)
  File "/home/ilkemirnurullah/.local/share/virtualenvs/Blog-0am4vL-A/lib/python3.5/site-packages/django/db/models/base.py", line 831, in _save_table
    result = self._do_insert(cls._base_manager, using, fields, update_pk, raw)
  File "/home/ilkemirnurullah/.local/share/virtualenvs/Blog-0am4vL-A/lib/python3.5/site-packages/django/db/models/base.py", line 869, in _do_insert
    using=using, raw=raw)
  File "/home/ilkemirnurullah/.local/share/virtualenvs/Blog-0am4vL-A/lib/python3.5/site-packages/django/db/models/manager.py", line 82, in manager_method
    return getattr(self.get_queryset(), name)(*args, **kwargs)
  File "/home/ilkemirnurullah/.local/share/virtualenvs/Blog-0am4vL-A/lib/python3.5/site-packages/django/db/models/query.py", line 1136, in _insert
    return query.get_compiler(using=using).execute_sql(return_id)
  File "/home/ilkemirnurullah/.local/share/virtualenvs/Blog-0am4vL-A/lib/python3.5/site-packages/django/db/models/sql/compiler.py", line 1289, in execute_sql
    cursor.execute(sql, params)
  File "/home/ilkemirnurullah/.local/share/virtualenvs/Blog-0am4vL-A/lib/python3.5/site-packages/django/db/backends/utils.py", line 68, in execute
    return self._execute_with_wrappers(sql, params, many=False, executor=self._execute)
  File "/home/ilkemirnurullah/.local/share/virtualenvs/Blog-0am4vL-A/lib/python3.5/site-packages/django/db/backends/utils.py", line 77, in _execute_with_wrappers
    return executor(sql, params, many, context)
  File "/home/ilkemirnurullah/.local/share/virtualenvs/Blog-0am4vL-A/lib/python3.5/site-packages/django/db/backends/utils.py", line 85, in _execute
    return self.cursor.execute(sql, params)
  File "/home/ilkemirnurullah/.local/share/virtualenvs/Blog-0am4vL-A/lib/python3.5/site-packages/django/db/utils.py", line 89, in __exit__
    raise dj_exc_value.with_traceback(traceback) from exc_value
  File "/home/ilkemirnurullah/.local/share/virtualenvs/Blog-0am4vL-A/lib/python3.5/site-packages/django/db/backends/utils.py", line 85, in _execute
    return self.cursor.execute(sql, params)
django.db.utils.IntegrityError: null value in column "comment_id" violates not-null constraint
DETAIL:  Failing row contains (Yorum, 2019-09-26 03:47:34.290823+00, 4, 2, null).

[2019-09-26 14:06:59] ERROR Invalid HTTP_HOST header: 'gthanks.googleplex.com'. You may need to add 'gthanks.googleplex.com' to ALLOWED_HOSTS.
[2019-09-28 22:39:39] ERROR Invalid HTTP_HOST header: '/run/gunicorn_mustakil.sock:'. The domain name provided is not valid according to RFC 1034/1035.
[2019-09-28 23:03:53] ERROR Internal Server Error: /articles/comment/4
Traceback (most recent call last):
  File "/home/ilkemirnurullah/.local/share/virtualenvs/Blog-0am4vL-A/lib/python3.5/site-packages/django/db/backends/utils.py", line 85, in _execute
    return self.cursor.execute(sql, params)
psycopg2.errors.NotNullViolation: null value in column "comment_id" violates not-null constraint
DETAIL:  Failing row contains (asdf, 2019-09-28 20:03:53.385529+00, 4, 2, null).


The above exception was the direct cause of the following exception:

Traceback (most recent call last):
  File "/home/ilkemirnurullah/.local/share/virtualenvs/Blog-0am4vL-A/lib/python3.5/site-packages/django/core/handlers/exception.py", line 34, in inner
    response = get_response(request)
  File "/home/ilkemirnurullah/.local/share/virtualenvs/Blog-0am4vL-A/lib/python3.5/site-packages/django/core/handlers/base.py", line 126, in _get_response
    response = self.process_exception_by_middleware(e, request)
  File "/home/ilkemirnurullah/.local/share/virtualenvs/Blog-0am4vL-A/lib/python3.5/site-packages/django/core/handlers/base.py", line 124, in _get_response
    response = wrapped_callback(request, *callback_args, **callback_kwargs)
  File "/home/ilkemirnurullah/.local/share/virtualenvs/Blog-0am4vL-A/lib/python3.5/site-packages/django/contrib/auth/decorators.py", line 21, in _wrapped_view
    return view_func(request, *args, **kwargs)
  File "/home/ilkemirnurullah/Blog/article/views.py", line 109, in addComment
    newComment.save()
  File "/home/ilkemirnurullah/.local/share/virtualenvs/Blog-0am4vL-A/lib/python3.5/site-packages/django/db/models/base.py", line 718, in save
    force_update=force_update, update_fields=update_fields)
  File "/home/ilkemirnurullah/.local/share/virtualenvs/Blog-0am4vL-A/lib/python3.5/site-packages/django/db/models/base.py", line 748, in save_base
    updated = self._save_table(raw, cls, force_insert, force_update, using, update_fields)
  File "/home/ilkemirnurullah/.local/share/virtualenvs/Blog-0am4vL-A/lib/python3.5/site-packages/django/db/models/base.py", line 831, in _save_table
    result = self._do_insert(cls._base_manager, using, fields, update_pk, raw)
  File "/home/ilkemirnurullah/.local/share/virtualenvs/Blog-0am4vL-A/lib/python3.5/site-packages/django/db/models/base.py", line 869, in _do_insert
    using=using, raw=raw)
  File "/home/ilkemirnurullah/.local/share/virtualenvs/Blog-0am4vL-A/lib/python3.5/site-packages/django/db/models/manager.py", line 82, in manager_method
    return getattr(self.get_queryset(), name)(*args, **kwargs)
  File "/home/ilkemirnurullah/.local/share/virtualenvs/Blog-0am4vL-A/lib/python3.5/site-packages/django/db/models/query.py", line 1136, in _insert
    return query.get_compiler(using=using).execute_sql(return_id)
  File "/home/ilkemirnurullah/.local/share/virtualenvs/Blog-0am4vL-A/lib/python3.5/site-packages/django/db/models/sql/compiler.py", line 1289, in execute_sql
    cursor.execute(sql, params)
  File "/home/ilkemirnurullah/.local/share/virtualenvs/Blog-0am4vL-A/lib/python3.5/site-packages/django/db/backends/utils.py", line 68, in execute
    return self._execute_with_wrappers(sql, params, many=False, executor=self._execute)
  File "/home/ilkemirnurullah/.local/share/virtualenvs/Blog-0am4vL-A/lib/python3.5/site-packages/django/db/backends/utils.py", line 77, in _execute_with_wrappers
    return executor(sql, params, many, context)
  File "/home/ilkemirnurullah/.local/share/virtualenvs/Blog-0am4vL-A/lib/python3.5/site-packages/django/db/backends/utils.py", line 85, in _execute
    return self.cursor.execute(sql, params)
  File "/home/ilkemirnurullah/.local/share/virtualenvs/Blog-0am4vL-A/lib/python3.5/site-packages/django/db/utils.py", line 89, in __exit__
    raise dj_exc_value.with_traceback(traceback) from exc_value
  File "/home/ilkemirnurullah/.local/share/virtualenvs/Blog-0am4vL-A/lib/python3.5/site-packages/django/db/backends/utils.py", line 85, in _execute
    return self.cursor.execute(sql, params)
django.db.utils.IntegrityError: null value in column "comment_id" violates not-null constraint
DETAIL:  Failing row contains (asdf, 2019-09-28 20:03:53.385529+00, 4, 2, null).

[2019-09-28 23:07:39] ERROR Internal Server Error: /articles/commentOfcomment/1
Traceback (most recent call last):
  File "/home/ilkemirnurullah/.local/share/virtualenvs/Blog-0am4vL-A/lib/python3.5/site-packages/django/db/backends/utils.py", line 85, in _execute
    return self.cursor.execute(sql, params)
psycopg2.errors.NotNullViolation: null value in column "commentOfComment_id" violates not-null constraint
DETAIL:  Failing row contains (asdf, 2019-09-28 20:07:39.928403+00, null, 2, 1, 3).


The above exception was the direct cause of the following exception:

Traceback (most recent call last):
  File "/home/ilkemirnurullah/.local/share/virtualenvs/Blog-0am4vL-A/lib/python3.5/site-packages/django/core/handlers/exception.py", line 34, in inner
    response = get_response(request)
  File "/home/ilkemirnurullah/.local/share/virtualenvs/Blog-0am4vL-A/lib/python3.5/site-packages/django/core/handlers/base.py", line 126, in _get_response
    response = self.process_exception_by_middleware(e, request)
  File "/home/ilkemirnurullah/.local/share/virtualenvs/Blog-0am4vL-A/lib/python3.5/site-packages/django/core/handlers/base.py", line 124, in _get_response
    response = wrapped_callback(request, *callback_args, **callback_kwargs)
  File "/home/ilkemirnurullah/.local/share/virtualenvs/Blog-0am4vL-A/lib/python3.5/site-packages/django/contrib/auth/decorators.py", line 21, in _wrapped_view
    return view_func(request, *args, **kwargs)
  File "/home/ilkemirnurullah/Blog/article/views.py", line 216, in addCommentofComment
    newCommentRe.save()
  File "/home/ilkemirnurullah/.local/share/virtualenvs/Blog-0am4vL-A/lib/python3.5/site-packages/django/db/models/base.py", line 718, in save
    force_update=force_update, update_fields=update_fields)
  File "/home/ilkemirnurullah/.local/share/virtualenvs/Blog-0am4vL-A/lib/python3.5/site-packages/django/db/models/base.py", line 748, in save_base
    updated = self._save_table(raw, cls, force_insert, force_update, using, update_fields)
  File "/home/ilkemirnurullah/.local/share/virtualenvs/Blog-0am4vL-A/lib/python3.5/site-packages/django/db/models/base.py", line 831, in _save_table
    result = self._do_insert(cls._base_manager, using, fields, update_pk, raw)
  File "/home/ilkemirnurullah/.local/share/virtualenvs/Blog-0am4vL-A/lib/python3.5/site-packages/django/db/models/base.py", line 869, in _do_insert
    using=using, raw=raw)
  File "/home/ilkemirnurullah/.local/share/virtualenvs/Blog-0am4vL-A/lib/python3.5/site-packages/django/db/models/manager.py", line 82, in manager_method
    return getattr(self.get_queryset(), name)(*args, **kwargs)
  File "/home/ilkemirnurullah/.local/share/virtualenvs/Blog-0am4vL-A/lib/python3.5/site-packages/django/db/models/query.py", line 1136, in _insert
    return query.get_compiler(using=using).execute_sql(return_id)
  File "/home/ilkemirnurullah/.local/share/virtualenvs/Blog-0am4vL-A/lib/python3.5/site-packages/django/db/models/sql/compiler.py", line 1289, in execute_sql
    cursor.execute(sql, params)
  File "/home/ilkemirnurullah/.local/share/virtualenvs/Blog-0am4vL-A/lib/python3.5/site-packages/django/db/backends/utils.py", line 68, in execute
    return self._execute_with_wrappers(sql, params, many=False, executor=self._execute)
  File "/home/ilkemirnurullah/.local/share/virtualenvs/Blog-0am4vL-A/lib/python3.5/site-packages/django/db/backends/utils.py", line 77, in _execute_with_wrappers
    return executor(sql, params, many, context)
  File "/home/ilkemirnurullah/.local/share/virtualenvs/Blog-0am4vL-A/lib/python3.5/site-packages/django/db/backends/utils.py", line 85, in _execute
    return self.cursor.execute(sql, params)
  File "/home/ilkemirnurullah/.local/share/virtualenvs/Blog-0am4vL-A/lib/python3.5/site-packages/django/db/utils.py", line 89, in __exit__
    raise dj_exc_value.with_traceback(traceback) from exc_value
  File "/home/ilkemirnurullah/.local/share/virtualenvs/Blog-0am4vL-A/lib/python3.5/site-packages/django/db/backends/utils.py", line 85, in _execute
    return self.cursor.execute(sql, params)
django.db.utils.IntegrityError: null value in column "commentOfComment_id" violates not-null constraint
DETAIL:  Failing row contains (asdf, 2019-09-28 20:07:39.928403+00, null, 2, 1, 3).

[2019-09-28 23:19:46] ERROR Internal Server Error: /articles/comment/5
Traceback (most recent call last):
  File "/home/ilkemirnurullah/.local/share/virtualenvs/Blog-0am4vL-A/lib/python3.5/site-packages/django/db/backends/utils.py", line 85, in _execute
    return self.cursor.execute(sql, params)
psycopg2.errors.NotNullViolation: null value in column "comment_id" violates not-null constraint
DETAIL:  Failing row contains (yeni yorum
, 2019-09-28 20:19:46.337311+00, 5, 2, null).


The above exception was the direct cause of the following exception:

Traceback (most recent call last):
  File "/home/ilkemirnurullah/.local/share/virtualenvs/Blog-0am4vL-A/lib/python3.5/site-packages/django/core/handlers/exception.py", line 34, in inner
    response = get_response(request)
  File "/home/ilkemirnurullah/.local/share/virtualenvs/Blog-0am4vL-A/lib/python3.5/site-packages/django/core/handlers/base.py", line 126, in _get_response
    response = self.process_exception_by_middleware(e, request)
  File "/home/ilkemirnurullah/.local/share/virtualenvs/Blog-0am4vL-A/lib/python3.5/site-packages/django/core/handlers/base.py", line 124, in _get_response
    response = wrapped_callback(request, *callback_args, **callback_kwargs)
  File "/home/ilkemirnurullah/.local/share/virtualenvs/Blog-0am4vL-A/lib/python3.5/site-packages/django/contrib/auth/decorators.py", line 21, in _wrapped_view
    return view_func(request, *args, **kwargs)
  File "/home/ilkemirnurullah/Blog/article/views.py", line 109, in addComment
    newComment.save()
  File "/home/ilkemirnurullah/.local/share/virtualenvs/Blog-0am4vL-A/lib/python3.5/site-packages/django/db/models/base.py", line 718, in save
    force_update=force_update, update_fields=update_fields)
  File "/home/ilkemirnurullah/.local/share/virtualenvs/Blog-0am4vL-A/lib/python3.5/site-packages/django/db/models/base.py", line 748, in save_base
    updated = self._save_table(raw, cls, force_insert, force_update, using, update_fields)
  File "/home/ilkemirnurullah/.local/share/virtualenvs/Blog-0am4vL-A/lib/python3.5/site-packages/django/db/models/base.py", line 831, in _save_table
    result = self._do_insert(cls._base_manager, using, fields, update_pk, raw)
  File "/home/ilkemirnurullah/.local/share/virtualenvs/Blog-0am4vL-A/lib/python3.5/site-packages/django/db/models/base.py", line 869, in _do_insert
    using=using, raw=raw)
  File "/home/ilkemirnurullah/.local/share/virtualenvs/Blog-0am4vL-A/lib/python3.5/site-packages/django/db/models/manager.py", line 82, in manager_method
    return getattr(self.get_queryset(), name)(*args, **kwargs)
  File "/home/ilkemirnurullah/.local/share/virtualenvs/Blog-0am4vL-A/lib/python3.5/site-packages/django/db/models/query.py", line 1136, in _insert
    return query.get_compiler(using=using).execute_sql(return_id)
  File "/home/ilkemirnurullah/.local/share/virtualenvs/Blog-0am4vL-A/lib/python3.5/site-packages/django/db/models/sql/compiler.py", line 1289, in execute_sql
    cursor.execute(sql, params)
  File "/home/ilkemirnurullah/.local/share/virtualenvs/Blog-0am4vL-A/lib/python3.5/site-packages/django/db/backends/utils.py", line 68, in execute
    return self._execute_with_wrappers(sql, params, many=False, executor=self._execute)
  File "/home/ilkemirnurullah/.local/share/virtualenvs/Blog-0am4vL-A/lib/python3.5/site-packages/django/db/backends/utils.py", line 77, in _execute_with_wrappers
    return executor(sql, params, many, context)
  File "/home/ilkemirnurullah/.local/share/virtualenvs/Blog-0am4vL-A/lib/python3.5/site-packages/django/db/backends/utils.py", line 85, in _execute
    return self.cursor.execute(sql, params)
  File "/home/ilkemirnurullah/.local/share/virtualenvs/Blog-0am4vL-A/lib/python3.5/site-packages/django/db/utils.py", line 89, in __exit__
    raise dj_exc_value.with_traceback(traceback) from exc_value
  File "/home/ilkemirnurullah/.local/share/virtualenvs/Blog-0am4vL-A/lib/python3.5/site-packages/django/db/backends/utils.py", line 85, in _execute
    return self.cursor.execute(sql, params)
django.db.utils.IntegrityError: null value in column "comment_id" violates not-null constraint
DETAIL:  Failing row contains (yeni yorum
, 2019-09-28 20:19:46.337311+00, 5, 2, null).

[2019-09-28 23:31:59] ERROR Internal Server Error: /articles/comment/5
Traceback (most recent call last):
  File "/home/ilkemirnurullah/.local/share/virtualenvs/Blog-0am4vL-A/lib/python3.5/site-packages/django/db/backends/utils.py", line 85, in _execute
    return self.cursor.execute(sql, params)
psycopg2.errors.NotNullViolation: null value in column "comment_id" violates not-null constraint
DETAIL:  Failing row contains (yeni yorum
, 2019-09-28 20:31:59.657458+00, 5, 2, null).


The above exception was the direct cause of the following exception:

Traceback (most recent call last):
  File "/home/ilkemirnurullah/.local/share/virtualenvs/Blog-0am4vL-A/lib/python3.5/site-packages/django/core/handlers/exception.py", line 34, in inner
    response = get_response(request)
  File "/home/ilkemirnurullah/.local/share/virtualenvs/Blog-0am4vL-A/lib/python3.5/site-packages/django/core/handlers/base.py", line 126, in _get_response
    response = self.process_exception_by_middleware(e, request)
  File "/home/ilkemirnurullah/.local/share/virtualenvs/Blog-0am4vL-A/lib/python3.5/site-packages/django/core/handlers/base.py", line 124, in _get_response
    response = wrapped_callback(request, *callback_args, **callback_kwargs)
  File "/home/ilkemirnurullah/.local/share/virtualenvs/Blog-0am4vL-A/lib/python3.5/site-packages/django/contrib/auth/decorators.py", line 21, in _wrapped_view
    return view_func(request, *args, **kwargs)
  File "/home/ilkemirnurullah/Blog/article/views.py", line 109, in addComment
    newComment.save()
  File "/home/ilkemirnurullah/.local/share/virtualenvs/Blog-0am4vL-A/lib/python3.5/site-packages/django/db/models/base.py", line 718, in save
    force_update=force_update, update_fields=update_fields)
  File "/home/ilkemirnurullah/.local/share/virtualenvs/Blog-0am4vL-A/lib/python3.5/site-packages/django/db/models/base.py", line 748, in save_base
    updated = self._save_table(raw, cls, force_insert, force_update, using, update_fields)
  File "/home/ilkemirnurullah/.local/share/virtualenvs/Blog-0am4vL-A/lib/python3.5/site-packages/django/db/models/base.py", line 831, in _save_table
    result = self._do_insert(cls._base_manager, using, fields, update_pk, raw)
  File "/home/ilkemirnurullah/.local/share/virtualenvs/Blog-0am4vL-A/lib/python3.5/site-packages/django/db/models/base.py", line 869, in _do_insert
    using=using, raw=raw)
  File "/home/ilkemirnurullah/.local/share/virtualenvs/Blog-0am4vL-A/lib/python3.5/site-packages/django/db/models/manager.py", line 82, in manager_method
    return getattr(self.get_queryset(), name)(*args, **kwargs)
  File "/home/ilkemirnurullah/.local/share/virtualenvs/Blog-0am4vL-A/lib/python3.5/site-packages/django/db/models/query.py", line 1136, in _insert
    return query.get_compiler(using=using).execute_sql(return_id)
  File "/home/ilkemirnurullah/.local/share/virtualenvs/Blog-0am4vL-A/lib/python3.5/site-packages/django/db/models/sql/compiler.py", line 1289, in execute_sql
    cursor.execute(sql, params)
  File "/home/ilkemirnurullah/.local/share/virtualenvs/Blog-0am4vL-A/lib/python3.5/site-packages/django/db/backends/utils.py", line 68, in execute
    return self._execute_with_wrappers(sql, params, many=False, executor=self._execute)
  File "/home/ilkemirnurullah/.local/share/virtualenvs/Blog-0am4vL-A/lib/python3.5/site-packages/django/db/backends/utils.py", line 77, in _execute_with_wrappers
    return executor(sql, params, many, context)
  File "/home/ilkemirnurullah/.local/share/virtualenvs/Blog-0am4vL-A/lib/python3.5/site-packages/django/db/backends/utils.py", line 85, in _execute
    return self.cursor.execute(sql, params)
  File "/home/ilkemirnurullah/.local/share/virtualenvs/Blog-0am4vL-A/lib/python3.5/site-packages/django/db/utils.py", line 89, in __exit__
    raise dj_exc_value.with_traceback(traceback) from exc_value
  File "/home/ilkemirnurullah/.local/share/virtualenvs/Blog-0am4vL-A/lib/python3.5/site-packages/django/db/backends/utils.py", line 85, in _execute
    return self.cursor.execute(sql, params)
django.db.utils.IntegrityError: null value in column "comment_id" violates not-null constraint
DETAIL:  Failing row contains (yeni yorum
, 2019-09-28 20:31:59.657458+00, 5, 2, null).

[2019-09-30 10:29:08] ERROR Internal Server Error: /articles/comment/5
Traceback (most recent call last):
  File "/home/ilkemirnurullah/.local/share/virtualenvs/Blog-0am4vL-A/lib/python3.5/site-packages/django/db/backends/utils.py", line 85, in _execute
    return self.cursor.execute(sql, params)
psycopg2.errors.NotNullViolation: null value in column "comment_id" violates not-null constraint
DETAIL:  Failing row contains (ffgf, 2019-09-30 07:29:08.440365+00, 5, 2, null).


The above exception was the direct cause of the following exception:

Traceback (most recent call last):
  File "/home/ilkemirnurullah/.local/share/virtualenvs/Blog-0am4vL-A/lib/python3.5/site-packages/django/core/handlers/exception.py", line 34, in inner
    response = get_response(request)
  File "/home/ilkemirnurullah/.local/share/virtualenvs/Blog-0am4vL-A/lib/python3.5/site-packages/django/core/handlers/base.py", line 126, in _get_response
    response = self.process_exception_by_middleware(e, request)
  File "/home/ilkemirnurullah/.local/share/virtualenvs/Blog-0am4vL-A/lib/python3.5/site-packages/django/core/handlers/base.py", line 124, in _get_response
    response = wrapped_callback(request, *callback_args, **callback_kwargs)
  File "/home/ilkemirnurullah/.local/share/virtualenvs/Blog-0am4vL-A/lib/python3.5/site-packages/django/contrib/auth/decorators.py", line 21, in _wrapped_view
    return view_func(request, *args, **kwargs)
  File "/home/ilkemirnurullah/Blog/article/views.py", line 109, in addComment
    newComment.save()
  File "/home/ilkemirnurullah/.local/share/virtualenvs/Blog-0am4vL-A/lib/python3.5/site-packages/django/db/models/base.py", line 718, in save
    force_update=force_update, update_fields=update_fields)
  File "/home/ilkemirnurullah/.local/share/virtualenvs/Blog-0am4vL-A/lib/python3.5/site-packages/django/db/models/base.py", line 748, in save_base
    updated = self._save_table(raw, cls, force_insert, force_update, using, update_fields)
  File "/home/ilkemirnurullah/.local/share/virtualenvs/Blog-0am4vL-A/lib/python3.5/site-packages/django/db/models/base.py", line 831, in _save_table
    result = self._do_insert(cls._base_manager, using, fields, update_pk, raw)
  File "/home/ilkemirnurullah/.local/share/virtualenvs/Blog-0am4vL-A/lib/python3.5/site-packages/django/db/models/base.py", line 869, in _do_insert
    using=using, raw=raw)
  File "/home/ilkemirnurullah/.local/share/virtualenvs/Blog-0am4vL-A/lib/python3.5/site-packages/django/db/models/manager.py", line 82, in manager_method
    return getattr(self.get_queryset(), name)(*args, **kwargs)
  File "/home/ilkemirnurullah/.local/share/virtualenvs/Blog-0am4vL-A/lib/python3.5/site-packages/django/db/models/query.py", line 1136, in _insert
    return query.get_compiler(using=using).execute_sql(return_id)
  File "/home/ilkemirnurullah/.local/share/virtualenvs/Blog-0am4vL-A/lib/python3.5/site-packages/django/db/models/sql/compiler.py", line 1289, in execute_sql
    cursor.execute(sql, params)
  File "/home/ilkemirnurullah/.local/share/virtualenvs/Blog-0am4vL-A/lib/python3.5/site-packages/django/db/backends/utils.py", line 68, in execute
    return self._execute_with_wrappers(sql, params, many=False, executor=self._execute)
  File "/home/ilkemirnurullah/.local/share/virtualenvs/Blog-0am4vL-A/lib/python3.5/site-packages/django/db/backends/utils.py", line 77, in _execute_with_wrappers
    return executor(sql, params, many, context)
  File "/home/ilkemirnurullah/.local/share/virtualenvs/Blog-0am4vL-A/lib/python3.5/site-packages/django/db/backends/utils.py", line 85, in _execute
    return self.cursor.execute(sql, params)
  File "/home/ilkemirnurullah/.local/share/virtualenvs/Blog-0am4vL-A/lib/python3.5/site-packages/django/db/utils.py", line 89, in __exit__
    raise dj_exc_value.with_traceback(traceback) from exc_value
  File "/home/ilkemirnurullah/.local/share/virtualenvs/Blog-0am4vL-A/lib/python3.5/site-packages/django/db/backends/utils.py", line 85, in _execute
    return self.cursor.execute(sql, params)
django.db.utils.IntegrityError: null value in column "comment_id" violates not-null constraint
DETAIL:  Failing row contains (ffgf, 2019-09-30 07:29:08.440365+00, 5, 2, null).

[2019-09-30 13:39:45] ERROR Internal Server Error: /articles/comment/5
Traceback (most recent call last):
  File "/home/ilkemirnurullah/.local/share/virtualenvs/Blog-0am4vL-A/lib/python3.5/site-packages/django/db/backends/utils.py", line 85, in _execute
    return self.cursor.execute(sql, params)
psycopg2.errors.NotNullViolation: null value in column "comment_id" violates not-null constraint
DETAIL:  Failing row contains (hggfvgrvffd, 2019-09-30 10:39:45.212521+00, 5, 2, null).


The above exception was the direct cause of the following exception:

Traceback (most recent call last):
  File "/home/ilkemirnurullah/.local/share/virtualenvs/Blog-0am4vL-A/lib/python3.5/site-packages/django/core/handlers/exception.py", line 34, in inner
    response = get_response(request)
  File "/home/ilkemirnurullah/.local/share/virtualenvs/Blog-0am4vL-A/lib/python3.5/site-packages/django/core/handlers/base.py", line 126, in _get_response
    response = self.process_exception_by_middleware(e, request)
  File "/home/ilkemirnurullah/.local/share/virtualenvs/Blog-0am4vL-A/lib/python3.5/site-packages/django/core/handlers/base.py", line 124, in _get_response
    response = wrapped_callback(request, *callback_args, **callback_kwargs)
  File "/home/ilkemirnurullah/.local/share/virtualenvs/Blog-0am4vL-A/lib/python3.5/site-packages/django/contrib/auth/decorators.py", line 21, in _wrapped_view
    return view_func(request, *args, **kwargs)
  File "/home/ilkemirnurullah/Blog/article/views.py", line 109, in addComment
    newComment.save()
  File "/home/ilkemirnurullah/.local/share/virtualenvs/Blog-0am4vL-A/lib/python3.5/site-packages/django/db/models/base.py", line 718, in save
    force_update=force_update, update_fields=update_fields)
  File "/home/ilkemirnurullah/.local/share/virtualenvs/Blog-0am4vL-A/lib/python3.5/site-packages/django/db/models/base.py", line 748, in save_base
    updated = self._save_table(raw, cls, force_insert, force_update, using, update_fields)
  File "/home/ilkemirnurullah/.local/share/virtualenvs/Blog-0am4vL-A/lib/python3.5/site-packages/django/db/models/base.py", line 831, in _save_table
    result = self._do_insert(cls._base_manager, using, fields, update_pk, raw)
  File "/home/ilkemirnurullah/.local/share/virtualenvs/Blog-0am4vL-A/lib/python3.5/site-packages/django/db/models/base.py", line 869, in _do_insert
    using=using, raw=raw)
  File "/home/ilkemirnurullah/.local/share/virtualenvs/Blog-0am4vL-A/lib/python3.5/site-packages/django/db/models/manager.py", line 82, in manager_method
    return getattr(self.get_queryset(), name)(*args, **kwargs)
  File "/home/ilkemirnurullah/.local/share/virtualenvs/Blog-0am4vL-A/lib/python3.5/site-packages/django/db/models/query.py", line 1136, in _insert
    return query.get_compiler(using=using).execute_sql(return_id)
  File "/home/ilkemirnurullah/.local/share/virtualenvs/Blog-0am4vL-A/lib/python3.5/site-packages/django/db/models/sql/compiler.py", line 1289, in execute_sql
    cursor.execute(sql, params)
  File "/home/ilkemirnurullah/.local/share/virtualenvs/Blog-0am4vL-A/lib/python3.5/site-packages/django/db/backends/utils.py", line 68, in execute
    return self._execute_with_wrappers(sql, params, many=False, executor=self._execute)
  File "/home/ilkemirnurullah/.local/share/virtualenvs/Blog-0am4vL-A/lib/python3.5/site-packages/django/db/backends/utils.py", line 77, in _execute_with_wrappers
    return executor(sql, params, many, context)
  File "/home/ilkemirnurullah/.local/share/virtualenvs/Blog-0am4vL-A/lib/python3.5/site-packages/django/db/backends/utils.py", line 85, in _execute
    return self.cursor.execute(sql, params)
  File "/home/ilkemirnurullah/.local/share/virtualenvs/Blog-0am4vL-A/lib/python3.5/site-packages/django/db/utils.py", line 89, in __exit__
    raise dj_exc_value.with_traceback(traceback) from exc_value
  File "/home/ilkemirnurullah/.local/share/virtualenvs/Blog-0am4vL-A/lib/python3.5/site-packages/django/db/backends/utils.py", line 85, in _execute
    return self.cursor.execute(sql, params)
django.db.utils.IntegrityError: null value in column "comment_id" violates not-null constraint
DETAIL:  Failing row contains (hggfvgrvffd, 2019-09-30 10:39:45.212521+00, 5, 2, null).

[2019-09-30 23:44:16] ERROR Internal Server Error: /articles/commentOfcomment/1
Traceback (most recent call last):
  File "/home/ilkemirnurullah/.local/share/virtualenvs/Blog-0am4vL-A/lib/python3.5/site-packages/django/db/backends/utils.py", line 85, in _execute
    return self.cursor.execute(sql, params)
psycopg2.errors.NotNullViolation: null value in column "commentOfComment_id" violates not-null constraint
DETAIL:  Failing row contains (yorum cevabı, 2019-09-30 20:44:16.314117+00, null, 2, 1, 5).


The above exception was the direct cause of the following exception:

Traceback (most recent call last):
  File "/home/ilkemirnurullah/.local/share/virtualenvs/Blog-0am4vL-A/lib/python3.5/site-packages/django/core/handlers/exception.py", line 34, in inner
    response = get_response(request)
  File "/home/ilkemirnurullah/.local/share/virtualenvs/Blog-0am4vL-A/lib/python3.5/site-packages/django/core/handlers/base.py", line 126, in _get_response
    response = self.process_exception_by_middleware(e, request)
  File "/home/ilkemirnurullah/.local/share/virtualenvs/Blog-0am4vL-A/lib/python3.5/site-packages/django/core/handlers/base.py", line 124, in _get_response
    response = wrapped_callback(request, *callback_args, **callback_kwargs)
  File "/home/ilkemirnurullah/.local/share/virtualenvs/Blog-0am4vL-A/lib/python3.5/site-packages/django/contrib/auth/decorators.py", line 21, in _wrapped_view
    return view_func(request, *args, **kwargs)
  File "/home/ilkemirnurullah/Blog/article/views.py", line 216, in addCommentofComment
    newCommentRe.save()
  File "/home/ilkemirnurullah/.local/share/virtualenvs/Blog-0am4vL-A/lib/python3.5/site-packages/django/db/models/base.py", line 718, in save
    force_update=force_update, update_fields=update_fields)
  File "/home/ilkemirnurullah/.local/share/virtualenvs/Blog-0am4vL-A/lib/python3.5/site-packages/django/db/models/base.py", line 748, in save_base
    updated = self._save_table(raw, cls, force_insert, force_update, using, update_fields)
  File "/home/ilkemirnurullah/.local/share/virtualenvs/Blog-0am4vL-A/lib/python3.5/site-packages/django/db/models/base.py", line 831, in _save_table
    result = self._do_insert(cls._base_manager, using, fields, update_pk, raw)
  File "/home/ilkemirnurullah/.local/share/virtualenvs/Blog-0am4vL-A/lib/python3.5/site-packages/django/db/models/base.py", line 869, in _do_insert
    using=using, raw=raw)
  File "/home/ilkemirnurullah/.local/share/virtualenvs/Blog-0am4vL-A/lib/python3.5/site-packages/django/db/models/manager.py", line 82, in manager_method
    return getattr(self.get_queryset(), name)(*args, **kwargs)
  File "/home/ilkemirnurullah/.local/share/virtualenvs/Blog-0am4vL-A/lib/python3.5/site-packages/django/db/models/query.py", line 1136, in _insert
    return query.get_compiler(using=using).execute_sql(return_id)
  File "/home/ilkemirnurullah/.local/share/virtualenvs/Blog-0am4vL-A/lib/python3.5/site-packages/django/db/models/sql/compiler.py", line 1289, in execute_sql
    cursor.execute(sql, params)
  File "/home/ilkemirnurullah/.local/share/virtualenvs/Blog-0am4vL-A/lib/python3.5/site-packages/django/db/backends/utils.py", line 68, in execute
    return self._execute_with_wrappers(sql, params, many=False, executor=self._execute)
  File "/home/ilkemirnurullah/.local/share/virtualenvs/Blog-0am4vL-A/lib/python3.5/site-packages/django/db/backends/utils.py", line 77, in _execute_with_wrappers
    return executor(sql, params, many, context)
  File "/home/ilkemirnurullah/.local/share/virtualenvs/Blog-0am4vL-A/lib/python3.5/site-packages/django/db/backends/utils.py", line 85, in _execute
    return self.cursor.execute(sql, params)
  File "/home/ilkemirnurullah/.local/share/virtualenvs/Blog-0am4vL-A/lib/python3.5/site-packages/django/db/utils.py", line 89, in __exit__
    raise dj_exc_value.with_traceback(traceback) from exc_value
  File "/home/ilkemirnurullah/.local/share/virtualenvs/Blog-0am4vL-A/lib/python3.5/site-packages/django/db/backends/utils.py", line 85, in _execute
    return self.cursor.execute(sql, params)
django.db.utils.IntegrityError: null value in column "commentOfComment_id" violates not-null constraint
DETAIL:  Failing row contains (yorum cevabı, 2019-09-30 20:44:16.314117+00, null, 2, 1, 5).

[2019-09-30 23:59:06] ERROR Internal Server Error: /articles/commentOfcomment/1
Traceback (most recent call last):
  File "/home/ilkemirnurullah/.local/share/virtualenvs/Blog-0am4vL-A/lib/python3.5/site-packages/django/db/backends/utils.py", line 85, in _execute
    return self.cursor.execute(sql, params)
psycopg2.errors.NotNullViolation: null value in column "commentOfComment_id" violates not-null constraint
DETAIL:  Failing row contains (yorum cevabı, 2019-09-30 20:59:06.958018+00, null, 2, 1, 5).


The above exception was the direct cause of the following exception:

Traceback (most recent call last):
  File "/home/ilkemirnurullah/.local/share/virtualenvs/Blog-0am4vL-A/lib/python3.5/site-packages/django/core/handlers/exception.py", line 34, in inner
    response = get_response(request)
  File "/home/ilkemirnurullah/.local/share/virtualenvs/Blog-0am4vL-A/lib/python3.5/site-packages/django/core/handlers/base.py", line 126, in _get_response
    response = self.process_exception_by_middleware(e, request)
  File "/home/ilkemirnurullah/.local/share/virtualenvs/Blog-0am4vL-A/lib/python3.5/site-packages/django/core/handlers/base.py", line 124, in _get_response
    response = wrapped_callback(request, *callback_args, **callback_kwargs)
  File "/home/ilkemirnurullah/.local/share/virtualenvs/Blog-0am4vL-A/lib/python3.5/site-packages/django/contrib/auth/decorators.py", line 21, in _wrapped_view
    return view_func(request, *args, **kwargs)
  File "/home/ilkemirnurullah/Blog/article/views.py", line 216, in addCommentofComment
    newCommentRe.save()
  File "/home/ilkemirnurullah/.local/share/virtualenvs/Blog-0am4vL-A/lib/python3.5/site-packages/django/db/models/base.py", line 718, in save
    force_update=force_update, update_fields=update_fields)
  File "/home/ilkemirnurullah/.local/share/virtualenvs/Blog-0am4vL-A/lib/python3.5/site-packages/django/db/models/base.py", line 748, in save_base
    updated = self._save_table(raw, cls, force_insert, force_update, using, update_fields)
  File "/home/ilkemirnurullah/.local/share/virtualenvs/Blog-0am4vL-A/lib/python3.5/site-packages/django/db/models/base.py", line 831, in _save_table
    result = self._do_insert(cls._base_manager, using, fields, update_pk, raw)
  File "/home/ilkemirnurullah/.local/share/virtualenvs/Blog-0am4vL-A/lib/python3.5/site-packages/django/db/models/base.py", line 869, in _do_insert
    using=using, raw=raw)
  File "/home/ilkemirnurullah/.local/share/virtualenvs/Blog-0am4vL-A/lib/python3.5/site-packages/django/db/models/manager.py", line 82, in manager_method
    return getattr(self.get_queryset(), name)(*args, **kwargs)
  File "/home/ilkemirnurullah/.local/share/virtualenvs/Blog-0am4vL-A/lib/python3.5/site-packages/django/db/models/query.py", line 1136, in _insert
    return query.get_compiler(using=using).execute_sql(return_id)
  File "/home/ilkemirnurullah/.local/share/virtualenvs/Blog-0am4vL-A/lib/python3.5/site-packages/django/db/models/sql/compiler.py", line 1289, in execute_sql
    cursor.execute(sql, params)
  File "/home/ilkemirnurullah/.local/share/virtualenvs/Blog-0am4vL-A/lib/python3.5/site-packages/django/db/backends/utils.py", line 68, in execute
    return self._execute_with_wrappers(sql, params, many=False, executor=self._execute)
  File "/home/ilkemirnurullah/.local/share/virtualenvs/Blog-0am4vL-A/lib/python3.5/site-packages/django/db/backends/utils.py", line 77, in _execute_with_wrappers
    return executor(sql, params, many, context)
  File "/home/ilkemirnurullah/.local/share/virtualenvs/Blog-0am4vL-A/lib/python3.5/site-packages/django/db/backends/utils.py", line 85, in _execute
    return self.cursor.execute(sql, params)
  File "/home/ilkemirnurullah/.local/share/virtualenvs/Blog-0am4vL-A/lib/python3.5/site-packages/django/db/utils.py", line 89, in __exit__
    raise dj_exc_value.with_traceback(traceback) from exc_value
  File "/home/ilkemirnurullah/.local/share/virtualenvs/Blog-0am4vL-A/lib/python3.5/site-packages/django/db/backends/utils.py", line 85, in _execute
    return self.cursor.execute(sql, params)
django.db.utils.IntegrityError: null value in column "commentOfComment_id" violates not-null constraint
DETAIL:  Failing row contains (yorum cevabı, 2019-09-30 20:59:06.958018+00, null, 2, 1, 5).

[2019-10-01 16:37:44] ERROR Internal Server Error: /articles/commentOfcomment/1
Traceback (most recent call last):
  File "/home/ilkemirnurullah/.local/share/virtualenvs/Blog-0am4vL-A/lib/python3.5/site-packages/django/db/backends/utils.py", line 85, in _execute
    return self.cursor.execute(sql, params)
psycopg2.errors.NotNullViolation: null value in column "commentOfComment_id" violates not-null constraint
DETAIL:  Failing row contains (yorum cevabı, 2019-10-01 13:37:44.919757+00, null, 2, 1, 5).


The above exception was the direct cause of the following exception:

Traceback (most recent call last):
  File "/home/ilkemirnurullah/.local/share/virtualenvs/Blog-0am4vL-A/lib/python3.5/site-packages/django/core/handlers/exception.py", line 34, in inner
    response = get_response(request)
  File "/home/ilkemirnurullah/.local/share/virtualenvs/Blog-0am4vL-A/lib/python3.5/site-packages/django/core/handlers/base.py", line 126, in _get_response
    response = self.process_exception_by_middleware(e, request)
  File "/home/ilkemirnurullah/.local/share/virtualenvs/Blog-0am4vL-A/lib/python3.5/site-packages/django/core/handlers/base.py", line 124, in _get_response
    response = wrapped_callback(request, *callback_args, **callback_kwargs)
  File "/home/ilkemirnurullah/.local/share/virtualenvs/Blog-0am4vL-A/lib/python3.5/site-packages/django/contrib/auth/decorators.py", line 21, in _wrapped_view
    return view_func(request, *args, **kwargs)
  File "/home/ilkemirnurullah/Blog/article/views.py", line 216, in addCommentofComment
    newCommentRe.save()
  File "/home/ilkemirnurullah/.local/share/virtualenvs/Blog-0am4vL-A/lib/python3.5/site-packages/django/db/models/base.py", line 718, in save
    force_update=force_update, update_fields=update_fields)
  File "/home/ilkemirnurullah/.local/share/virtualenvs/Blog-0am4vL-A/lib/python3.5/site-packages/django/db/models/base.py", line 748, in save_base
    updated = self._save_table(raw, cls, force_insert, force_update, using, update_fields)
  File "/home/ilkemirnurullah/.local/share/virtualenvs/Blog-0am4vL-A/lib/python3.5/site-packages/django/db/models/base.py", line 831, in _save_table
    result = self._do_insert(cls._base_manager, using, fields, update_pk, raw)
  File "/home/ilkemirnurullah/.local/share/virtualenvs/Blog-0am4vL-A/lib/python3.5/site-packages/django/db/models/base.py", line 869, in _do_insert
    using=using, raw=raw)
  File "/home/ilkemirnurullah/.local/share/virtualenvs/Blog-0am4vL-A/lib/python3.5/site-packages/django/db/models/manager.py", line 82, in manager_method
    return getattr(self.get_queryset(), name)(*args, **kwargs)
  File "/home/ilkemirnurullah/.local/share/virtualenvs/Blog-0am4vL-A/lib/python3.5/site-packages/django/db/models/query.py", line 1136, in _insert
    return query.get_compiler(using=using).execute_sql(return_id)
  File "/home/ilkemirnurullah/.local/share/virtualenvs/Blog-0am4vL-A/lib/python3.5/site-packages/django/db/models/sql/compiler.py", line 1289, in execute_sql
    cursor.execute(sql, params)
  File "/home/ilkemirnurullah/.local/share/virtualenvs/Blog-0am4vL-A/lib/python3.5/site-packages/django/db/backends/utils.py", line 68, in execute
    return self._execute_with_wrappers(sql, params, many=False, executor=self._execute)
  File "/home/ilkemirnurullah/.local/share/virtualenvs/Blog-0am4vL-A/lib/python3.5/site-packages/django/db/backends/utils.py", line 77, in _execute_with_wrappers
    return executor(sql, params, many, context)
  File "/home/ilkemirnurullah/.local/share/virtualenvs/Blog-0am4vL-A/lib/python3.5/site-packages/django/db/backends/utils.py", line 85, in _execute
    return self.cursor.execute(sql, params)
  File "/home/ilkemirnurullah/.local/share/virtualenvs/Blog-0am4vL-A/lib/python3.5/site-packages/django/db/utils.py", line 89, in __exit__
    raise dj_exc_value.with_traceback(traceback) from exc_value
  File "/home/ilkemirnurullah/.local/share/virtualenvs/Blog-0am4vL-A/lib/python3.5/site-packages/django/db/backends/utils.py", line 85, in _execute
    return self.cursor.execute(sql, params)
django.db.utils.IntegrityError: null value in column "commentOfComment_id" violates not-null constraint
DETAIL:  Failing row contains (yorum cevabı, 2019-10-01 13:37:44.919757+00, null, 2, 1, 5).

[2019-10-01 16:37:54] ERROR Internal Server Error: /articles/commentOfcomment/1
Traceback (most recent call last):
  File "/home/ilkemirnurullah/.local/share/virtualenvs/Blog-0am4vL-A/lib/python3.5/site-packages/django/db/backends/utils.py", line 85, in _execute
    return self.cursor.execute(sql, params)
psycopg2.errors.NotNullViolation: null value in column "commentOfComment_id" violates not-null constraint
DETAIL:  Failing row contains (yorum cevabı, 2019-10-01 13:37:54.676819+00, null, 2, 1, 5).


The above exception was the direct cause of the following exception:

Traceback (most recent call last):
  File "/home/ilkemirnurullah/.local/share/virtualenvs/Blog-0am4vL-A/lib/python3.5/site-packages/django/core/handlers/exception.py", line 34, in inner
    response = get_response(request)
  File "/home/ilkemirnurullah/.local/share/virtualenvs/Blog-0am4vL-A/lib/python3.5/site-packages/django/core/handlers/base.py", line 126, in _get_response
    response = self.process_exception_by_middleware(e, request)
  File "/home/ilkemirnurullah/.local/share/virtualenvs/Blog-0am4vL-A/lib/python3.5/site-packages/django/core/handlers/base.py", line 124, in _get_response
    response = wrapped_callback(request, *callback_args, **callback_kwargs)
  File "/home/ilkemirnurullah/.local/share/virtualenvs/Blog-0am4vL-A/lib/python3.5/site-packages/django/contrib/auth/decorators.py", line 21, in _wrapped_view
    return view_func(request, *args, **kwargs)
  File "/home/ilkemirnurullah/Blog/article/views.py", line 216, in addCommentofComment
    newCommentRe.save()
  File "/home/ilkemirnurullah/.local/share/virtualenvs/Blog-0am4vL-A/lib/python3.5/site-packages/django/db/models/base.py", line 718, in save
    force_update=force_update, update_fields=update_fields)
  File "/home/ilkemirnurullah/.local/share/virtualenvs/Blog-0am4vL-A/lib/python3.5/site-packages/django/db/models/base.py", line 748, in save_base
    updated = self._save_table(raw, cls, force_insert, force_update, using, update_fields)
  File "/home/ilkemirnurullah/.local/share/virtualenvs/Blog-0am4vL-A/lib/python3.5/site-packages/django/db/models/base.py", line 831, in _save_table
    result = self._do_insert(cls._base_manager, using, fields, update_pk, raw)
  File "/home/ilkemirnurullah/.local/share/virtualenvs/Blog-0am4vL-A/lib/python3.5/site-packages/django/db/models/base.py", line 869, in _do_insert
    using=using, raw=raw)
  File "/home/ilkemirnurullah/.local/share/virtualenvs/Blog-0am4vL-A/lib/python3.5/site-packages/django/db/models/manager.py", line 82, in manager_method
    return getattr(self.get_queryset(), name)(*args, **kwargs)
  File "/home/ilkemirnurullah/.local/share/virtualenvs/Blog-0am4vL-A/lib/python3.5/site-packages/django/db/models/query.py", line 1136, in _insert
    return query.get_compiler(using=using).execute_sql(return_id)
  File "/home/ilkemirnurullah/.local/share/virtualenvs/Blog-0am4vL-A/lib/python3.5/site-packages/django/db/models/sql/compiler.py", line 1289, in execute_sql
    cursor.execute(sql, params)
  File "/home/ilkemirnurullah/.local/share/virtualenvs/Blog-0am4vL-A/lib/python3.5/site-packages/django/db/backends/utils.py", line 68, in execute
    return self._execute_with_wrappers(sql, params, many=False, executor=self._execute)
  File "/home/ilkemirnurullah/.local/share/virtualenvs/Blog-0am4vL-A/lib/python3.5/site-packages/django/db/backends/utils.py", line 77, in _execute_with_wrappers
    return executor(sql, params, many, context)
  File "/home/ilkemirnurullah/.local/share/virtualenvs/Blog-0am4vL-A/lib/python3.5/site-packages/django/db/backends/utils.py", line 85, in _execute
    return self.cursor.execute(sql, params)
  File "/home/ilkemirnurullah/.local/share/virtualenvs/Blog-0am4vL-A/lib/python3.5/site-packages/django/db/utils.py", line 89, in __exit__
    raise dj_exc_value.with_traceback(traceback) from exc_value
  File "/home/ilkemirnurullah/.local/share/virtualenvs/Blog-0am4vL-A/lib/python3.5/site-packages/django/db/backends/utils.py", line 85, in _execute
    return self.cursor.execute(sql, params)
django.db.utils.IntegrityError: null value in column "commentOfComment_id" violates not-null constraint
DETAIL:  Failing row contains (yorum cevabı, 2019-10-01 13:37:54.676819+00, null, 2, 1, 5).

[2019-10-01 16:38:11] ERROR Internal Server Error: /articles/commentOfcomment/2
Traceback (most recent call last):
  File "/home/ilkemirnurullah/.local/share/virtualenvs/Blog-0am4vL-A/lib/python3.5/site-packages/django/db/backends/utils.py", line 85, in _execute
    return self.cursor.execute(sql, params)
psycopg2.errors.NotNullViolation: null value in column "commentOfComment_id" violates not-null constraint
DETAIL:  Failing row contains (asda, 2019-10-01 13:38:11.542955+00, null, 2, 2, 5).


The above exception was the direct cause of the following exception:

Traceback (most recent call last):
  File "/home/ilkemirnurullah/.local/share/virtualenvs/Blog-0am4vL-A/lib/python3.5/site-packages/django/core/handlers/exception.py", line 34, in inner
    response = get_response(request)
  File "/home/ilkemirnurullah/.local/share/virtualenvs/Blog-0am4vL-A/lib/python3.5/site-packages/django/core/handlers/base.py", line 126, in _get_response
    response = self.process_exception_by_middleware(e, request)
  File "/home/ilkemirnurullah/.local/share/virtualenvs/Blog-0am4vL-A/lib/python3.5/site-packages/django/core/handlers/base.py", line 124, in _get_response
    response = wrapped_callback(request, *callback_args, **callback_kwargs)
  File "/home/ilkemirnurullah/.local/share/virtualenvs/Blog-0am4vL-A/lib/python3.5/site-packages/django/contrib/auth/decorators.py", line 21, in _wrapped_view
    return view_func(request, *args, **kwargs)
  File "/home/ilkemirnurullah/Blog/article/views.py", line 216, in addCommentofComment
    newCommentRe.save()
  File "/home/ilkemirnurullah/.local/share/virtualenvs/Blog-0am4vL-A/lib/python3.5/site-packages/django/db/models/base.py", line 718, in save
    force_update=force_update, update_fields=update_fields)
  File "/home/ilkemirnurullah/.local/share/virtualenvs/Blog-0am4vL-A/lib/python3.5/site-packages/django/db/models/base.py", line 748, in save_base
    updated = self._save_table(raw, cls, force_insert, force_update, using, update_fields)
  File "/home/ilkemirnurullah/.local/share/virtualenvs/Blog-0am4vL-A/lib/python3.5/site-packages/django/db/models/base.py", line 831, in _save_table
    result = self._do_insert(cls._base_manager, using, fields, update_pk, raw)
  File "/home/ilkemirnurullah/.local/share/virtualenvs/Blog-0am4vL-A/lib/python3.5/site-packages/django/db/models/base.py", line 869, in _do_insert
    using=using, raw=raw)
  File "/home/ilkemirnurullah/.local/share/virtualenvs/Blog-0am4vL-A/lib/python3.5/site-packages/django/db/models/manager.py", line 82, in manager_method
    return getattr(self.get_queryset(), name)(*args, **kwargs)
  File "/home/ilkemirnurullah/.local/share/virtualenvs/Blog-0am4vL-A/lib/python3.5/site-packages/django/db/models/query.py", line 1136, in _insert
    return query.get_compiler(using=using).execute_sql(return_id)
  File "/home/ilkemirnurullah/.local/share/virtualenvs/Blog-0am4vL-A/lib/python3.5/site-packages/django/db/models/sql/compiler.py", line 1289, in execute_sql
    cursor.execute(sql, params)
  File "/home/ilkemirnurullah/.local/share/virtualenvs/Blog-0am4vL-A/lib/python3.5/site-packages/django/db/backends/utils.py", line 68, in execute
    return self._execute_with_wrappers(sql, params, many=False, executor=self._execute)
  File "/home/ilkemirnurullah/.local/share/virtualenvs/Blog-0am4vL-A/lib/python3.5/site-packages/django/db/backends/utils.py", line 77, in _execute_with_wrappers
    return executor(sql, params, many, context)
  File "/home/ilkemirnurullah/.local/share/virtualenvs/Blog-0am4vL-A/lib/python3.5/site-packages/django/db/backends/utils.py", line 85, in _execute
    return self.cursor.execute(sql, params)
  File "/home/ilkemirnurullah/.local/share/virtualenvs/Blog-0am4vL-A/lib/python3.5/site-packages/django/db/utils.py", line 89, in __exit__
    raise dj_exc_value.with_traceback(traceback) from exc_value
  File "/home/ilkemirnurullah/.local/share/virtualenvs/Blog-0am4vL-A/lib/python3.5/site-packages/django/db/backends/utils.py", line 85, in _execute
    return self.cursor.execute(sql, params)
django.db.utils.IntegrityError: null value in column "commentOfComment_id" violates not-null constraint
DETAIL:  Failing row contains (asda, 2019-10-01 13:38:11.542955+00, null, 2, 2, 5).

[2019-10-01 16:38:55] ERROR Internal Server Error: /articles/commentOfcomment/2
Traceback (most recent call last):
  File "/home/ilkemirnurullah/.local/share/virtualenvs/Blog-0am4vL-A/lib/python3.5/site-packages/django/db/backends/utils.py", line 85, in _execute
    return self.cursor.execute(sql, params)
psycopg2.errors.NotNullViolation: null value in column "commentOfComment_id" violates not-null constraint
DETAIL:  Failing row contains (asda, 2019-10-01 13:38:55.122433+00, null, 2, 2, 5).


The above exception was the direct cause of the following exception:

Traceback (most recent call last):
  File "/home/ilkemirnurullah/.local/share/virtualenvs/Blog-0am4vL-A/lib/python3.5/site-packages/django/core/handlers/exception.py", line 34, in inner
    response = get_response(request)
  File "/home/ilkemirnurullah/.local/share/virtualenvs/Blog-0am4vL-A/lib/python3.5/site-packages/django/core/handlers/base.py", line 126, in _get_response
    response = self.process_exception_by_middleware(e, request)
  File "/home/ilkemirnurullah/.local/share/virtualenvs/Blog-0am4vL-A/lib/python3.5/site-packages/django/core/handlers/base.py", line 124, in _get_response
    response = wrapped_callback(request, *callback_args, **callback_kwargs)
  File "/home/ilkemirnurullah/.local/share/virtualenvs/Blog-0am4vL-A/lib/python3.5/site-packages/django/contrib/auth/decorators.py", line 21, in _wrapped_view
    return view_func(request, *args, **kwargs)
  File "/home/ilkemirnurullah/Blog/article/views.py", line 216, in addCommentofComment
    newCommentRe.save()
  File "/home/ilkemirnurullah/.local/share/virtualenvs/Blog-0am4vL-A/lib/python3.5/site-packages/django/db/models/base.py", line 718, in save
    force_update=force_update, update_fields=update_fields)
  File "/home/ilkemirnurullah/.local/share/virtualenvs/Blog-0am4vL-A/lib/python3.5/site-packages/django/db/models/base.py", line 748, in save_base
    updated = self._save_table(raw, cls, force_insert, force_update, using, update_fields)
  File "/home/ilkemirnurullah/.local/share/virtualenvs/Blog-0am4vL-A/lib/python3.5/site-packages/django/db/models/base.py", line 831, in _save_table
    result = self._do_insert(cls._base_manager, using, fields, update_pk, raw)
  File "/home/ilkemirnurullah/.local/share/virtualenvs/Blog-0am4vL-A/lib/python3.5/site-packages/django/db/models/base.py", line 869, in _do_insert
    using=using, raw=raw)
  File "/home/ilkemirnurullah/.local/share/virtualenvs/Blog-0am4vL-A/lib/python3.5/site-packages/django/db/models/manager.py", line 82, in manager_method
    return getattr(self.get_queryset(), name)(*args, **kwargs)
  File "/home/ilkemirnurullah/.local/share/virtualenvs/Blog-0am4vL-A/lib/python3.5/site-packages/django/db/models/query.py", line 1136, in _insert
    return query.get_compiler(using=using).execute_sql(return_id)
  File "/home/ilkemirnurullah/.local/share/virtualenvs/Blog-0am4vL-A/lib/python3.5/site-packages/django/db/models/sql/compiler.py", line 1289, in execute_sql
    cursor.execute(sql, params)
  File "/home/ilkemirnurullah/.local/share/virtualenvs/Blog-0am4vL-A/lib/python3.5/site-packages/django/db/backends/utils.py", line 68, in execute
    return self._execute_with_wrappers(sql, params, many=False, executor=self._execute)
  File "/home/ilkemirnurullah/.local/share/virtualenvs/Blog-0am4vL-A/lib/python3.5/site-packages/django/db/backends/utils.py", line 77, in _execute_with_wrappers
    return executor(sql, params, many, context)
  File "/home/ilkemirnurullah/.local/share/virtualenvs/Blog-0am4vL-A/lib/python3.5/site-packages/django/db/backends/utils.py", line 85, in _execute
    return self.cursor.execute(sql, params)
  File "/home/ilkemirnurullah/.local/share/virtualenvs/Blog-0am4vL-A/lib/python3.5/site-packages/django/db/utils.py", line 89, in __exit__
    raise dj_exc_value.with_traceback(traceback) from exc_value
  File "/home/ilkemirnurullah/.local/share/virtualenvs/Blog-0am4vL-A/lib/python3.5/site-packages/django/db/backends/utils.py", line 85, in _execute
    return self.cursor.execute(sql, params)
django.db.utils.IntegrityError: null value in column "commentOfComment_id" violates not-null constraint
DETAIL:  Failing row contains (asda, 2019-10-01 13:38:55.122433+00, null, 2, 2, 5).

[2019-10-01 16:48:56] ERROR Internal Server Error: /articles/commentOfcomment/2
Traceback (most recent call last):
  File "/home/ilkemirnurullah/.local/share/virtualenvs/Blog-0am4vL-A/lib/python3.5/site-packages/django/db/backends/utils.py", line 85, in _execute
    return self.cursor.execute(sql, params)
psycopg2.errors.NotNullViolation: null value in column "commentOfComment_id" violates not-null constraint
DETAIL:  Failing row contains (asdaqweqeqweeqwe, 2019-10-01 13:48:56.061829+00, null, 2, 2, 5).


The above exception was the direct cause of the following exception:

Traceback (most recent call last):
  File "/home/ilkemirnurullah/.local/share/virtualenvs/Blog-0am4vL-A/lib/python3.5/site-packages/django/core/handlers/exception.py", line 34, in inner
    response = get_response(request)
  File "/home/ilkemirnurullah/.local/share/virtualenvs/Blog-0am4vL-A/lib/python3.5/site-packages/django/core/handlers/base.py", line 126, in _get_response
    response = self.process_exception_by_middleware(e, request)
  File "/home/ilkemirnurullah/.local/share/virtualenvs/Blog-0am4vL-A/lib/python3.5/site-packages/django/core/handlers/base.py", line 124, in _get_response
    response = wrapped_callback(request, *callback_args, **callback_kwargs)
  File "/home/ilkemirnurullah/.local/share/virtualenvs/Blog-0am4vL-A/lib/python3.5/site-packages/django/contrib/auth/decorators.py", line 21, in _wrapped_view
    return view_func(request, *args, **kwargs)
  File "/home/ilkemirnurullah/Blog/article/views.py", line 216, in addCommentofComment
    newCommentRe.save()
  File "/home/ilkemirnurullah/.local/share/virtualenvs/Blog-0am4vL-A/lib/python3.5/site-packages/django/db/models/base.py", line 718, in save
    force_update=force_update, update_fields=update_fields)
  File "/home/ilkemirnurullah/.local/share/virtualenvs/Blog-0am4vL-A/lib/python3.5/site-packages/django/db/models/base.py", line 748, in save_base
    updated = self._save_table(raw, cls, force_insert, force_update, using, update_fields)
  File "/home/ilkemirnurullah/.local/share/virtualenvs/Blog-0am4vL-A/lib/python3.5/site-packages/django/db/models/base.py", line 831, in _save_table
    result = self._do_insert(cls._base_manager, using, fields, update_pk, raw)
  File "/home/ilkemirnurullah/.local/share/virtualenvs/Blog-0am4vL-A/lib/python3.5/site-packages/django/db/models/base.py", line 869, in _do_insert
    using=using, raw=raw)
  File "/home/ilkemirnurullah/.local/share/virtualenvs/Blog-0am4vL-A/lib/python3.5/site-packages/django/db/models/manager.py", line 82, in manager_method
    return getattr(self.get_queryset(), name)(*args, **kwargs)
  File "/home/ilkemirnurullah/.local/share/virtualenvs/Blog-0am4vL-A/lib/python3.5/site-packages/django/db/models/query.py", line 1136, in _insert
    return query.get_compiler(using=using).execute_sql(return_id)
  File "/home/ilkemirnurullah/.local/share/virtualenvs/Blog-0am4vL-A/lib/python3.5/site-packages/django/db/models/sql/compiler.py", line 1289, in execute_sql
    cursor.execute(sql, params)
  File "/home/ilkemirnurullah/.local/share/virtualenvs/Blog-0am4vL-A/lib/python3.5/site-packages/django/db/backends/utils.py", line 68, in execute
    return self._execute_with_wrappers(sql, params, many=False, executor=self._execute)
  File "/home/ilkemirnurullah/.local/share/virtualenvs/Blog-0am4vL-A/lib/python3.5/site-packages/django/db/backends/utils.py", line 77, in _execute_with_wrappers
    return executor(sql, params, many, context)
  File "/home/ilkemirnurullah/.local/share/virtualenvs/Blog-0am4vL-A/lib/python3.5/site-packages/django/db/backends/utils.py", line 85, in _execute
    return self.cursor.execute(sql, params)
  File "/home/ilkemirnurullah/.local/share/virtualenvs/Blog-0am4vL-A/lib/python3.5/site-packages/django/db/utils.py", line 89, in __exit__
    raise dj_exc_value.with_traceback(traceback) from exc_value
  File "/home/ilkemirnurullah/.local/share/virtualenvs/Blog-0am4vL-A/lib/python3.5/site-packages/django/db/backends/utils.py", line 85, in _execute
    return self.cursor.execute(sql, params)
django.db.utils.IntegrityError: null value in column "commentOfComment_id" violates not-null constraint
DETAIL:  Failing row contains (asdaqweqeqweeqwe, 2019-10-01 13:48:56.061829+00, null, 2, 2, 5).

[2019-10-01 16:56:06] ERROR Internal Server Error: /articles/commentOfcomment/2
Traceback (most recent call last):
  File "/home/ilkemirnurullah/.local/share/virtualenvs/Blog-0am4vL-A/lib/python3.5/site-packages/django/db/backends/utils.py", line 85, in _execute
    return self.cursor.execute(sql, params)
psycopg2.errors.NotNullViolation: null value in column "commentOfComment_id" violates not-null constraint
DETAIL:  Failing row contains (asdaqweqeqweeqwe, 2019-10-01 13:56:06.405106+00, null, 2, 2, 5).


The above exception was the direct cause of the following exception:

Traceback (most recent call last):
  File "/home/ilkemirnurullah/.local/share/virtualenvs/Blog-0am4vL-A/lib/python3.5/site-packages/django/core/handlers/exception.py", line 34, in inner
    response = get_response(request)
  File "/home/ilkemirnurullah/.local/share/virtualenvs/Blog-0am4vL-A/lib/python3.5/site-packages/django/core/handlers/base.py", line 126, in _get_response
    response = self.process_exception_by_middleware(e, request)
  File "/home/ilkemirnurullah/.local/share/virtualenvs/Blog-0am4vL-A/lib/python3.5/site-packages/django/core/handlers/base.py", line 124, in _get_response
    response = wrapped_callback(request, *callback_args, **callback_kwargs)
  File "/home/ilkemirnurullah/.local/share/virtualenvs/Blog-0am4vL-A/lib/python3.5/site-packages/django/contrib/auth/decorators.py", line 21, in _wrapped_view
    return view_func(request, *args, **kwargs)
  File "/home/ilkemirnurullah/Blog/article/views.py", line 216, in addCommentofComment
    newCommentRe.save()
  File "/home/ilkemirnurullah/.local/share/virtualenvs/Blog-0am4vL-A/lib/python3.5/site-packages/django/db/models/base.py", line 718, in save
    force_update=force_update, update_fields=update_fields)
  File "/home/ilkemirnurullah/.local/share/virtualenvs/Blog-0am4vL-A/lib/python3.5/site-packages/django/db/models/base.py", line 748, in save_base
    updated = self._save_table(raw, cls, force_insert, force_update, using, update_fields)
  File "/home/ilkemirnurullah/.local/share/virtualenvs/Blog-0am4vL-A/lib/python3.5/site-packages/django/db/models/base.py", line 831, in _save_table
    result = self._do_insert(cls._base_manager, using, fields, update_pk, raw)
  File "/home/ilkemirnurullah/.local/share/virtualenvs/Blog-0am4vL-A/lib/python3.5/site-packages/django/db/models/base.py", line 869, in _do_insert
    using=using, raw=raw)
  File "/home/ilkemirnurullah/.local/share/virtualenvs/Blog-0am4vL-A/lib/python3.5/site-packages/django/db/models/manager.py", line 82, in manager_method
    return getattr(self.get_queryset(), name)(*args, **kwargs)
  File "/home/ilkemirnurullah/.local/share/virtualenvs/Blog-0am4vL-A/lib/python3.5/site-packages/django/db/models/query.py", line 1136, in _insert
    return query.get_compiler(using=using).execute_sql(return_id)
  File "/home/ilkemirnurullah/.local/share/virtualenvs/Blog-0am4vL-A/lib/python3.5/site-packages/django/db/models/sql/compiler.py", line 1289, in execute_sql
    cursor.execute(sql, params)
  File "/home/ilkemirnurullah/.local/share/virtualenvs/Blog-0am4vL-A/lib/python3.5/site-packages/django/db/backends/utils.py", line 68, in execute
    return self._execute_with_wrappers(sql, params, many=False, executor=self._execute)
  File "/home/ilkemirnurullah/.local/share/virtualenvs/Blog-0am4vL-A/lib/python3.5/site-packages/django/db/backends/utils.py", line 77, in _execute_with_wrappers
    return executor(sql, params, many, context)
  File "/home/ilkemirnurullah/.local/share/virtualenvs/Blog-0am4vL-A/lib/python3.5/site-packages/django/db/backends/utils.py", line 85, in _execute
    return self.cursor.execute(sql, params)
  File "/home/ilkemirnurullah/.local/share/virtualenvs/Blog-0am4vL-A/lib/python3.5/site-packages/django/db/utils.py", line 89, in __exit__
    raise dj_exc_value.with_traceback(traceback) from exc_value
  File "/home/ilkemirnurullah/.local/share/virtualenvs/Blog-0am4vL-A/lib/python3.5/site-packages/django/db/backends/utils.py", line 85, in _execute
    return self.cursor.execute(sql, params)
django.db.utils.IntegrityError: null value in column "commentOfComment_id" violates not-null constraint
DETAIL:  Failing row contains (asdaqweqeqweeqwe, 2019-10-01 13:56:06.405106+00, null, 2, 2, 5).

[2019-10-01 18:59:26] ERROR Internal Server Error: /articles/commentOfcomment/3
Traceback (most recent call last):
  File "/home/ilkemirnurullah/.local/share/virtualenvs/Blog-0am4vL-A/lib/python3.5/site-packages/django/db/backends/utils.py", line 85, in _execute
    return self.cursor.execute(sql, params)
psycopg2.errors.NotNullViolation: null value in column "commentOfComment_id" violates not-null constraint
DETAIL:  Failing row contains (yorum cevabı, 2019-10-01 15:59:26.238312+00, null, 2, 3, 5).


The above exception was the direct cause of the following exception:

Traceback (most recent call last):
  File "/home/ilkemirnurullah/.local/share/virtualenvs/Blog-0am4vL-A/lib/python3.5/site-packages/django/core/handlers/exception.py", line 34, in inner
    response = get_response(request)
  File "/home/ilkemirnurullah/.local/share/virtualenvs/Blog-0am4vL-A/lib/python3.5/site-packages/django/core/handlers/base.py", line 126, in _get_response
    response = self.process_exception_by_middleware(e, request)
  File "/home/ilkemirnurullah/.local/share/virtualenvs/Blog-0am4vL-A/lib/python3.5/site-packages/django/core/handlers/base.py", line 124, in _get_response
    response = wrapped_callback(request, *callback_args, **callback_kwargs)
  File "/home/ilkemirnurullah/.local/share/virtualenvs/Blog-0am4vL-A/lib/python3.5/site-packages/django/contrib/auth/decorators.py", line 21, in _wrapped_view
    return view_func(request, *args, **kwargs)
  File "/home/ilkemirnurullah/Blog/article/views.py", line 216, in addCommentofComment
    newCommentRe.save()
  File "/home/ilkemirnurullah/.local/share/virtualenvs/Blog-0am4vL-A/lib/python3.5/site-packages/django/db/models/base.py", line 718, in save
    force_update=force_update, update_fields=update_fields)
  File "/home/ilkemirnurullah/.local/share/virtualenvs/Blog-0am4vL-A/lib/python3.5/site-packages/django/db/models/base.py", line 748, in save_base
    updated = self._save_table(raw, cls, force_insert, force_update, using, update_fields)
  File "/home/ilkemirnurullah/.local/share/virtualenvs/Blog-0am4vL-A/lib/python3.5/site-packages/django/db/models/base.py", line 831, in _save_table
    result = self._do_insert(cls._base_manager, using, fields, update_pk, raw)
  File "/home/ilkemirnurullah/.local/share/virtualenvs/Blog-0am4vL-A/lib/python3.5/site-packages/django/db/models/base.py", line 869, in _do_insert
    using=using, raw=raw)
  File "/home/ilkemirnurullah/.local/share/virtualenvs/Blog-0am4vL-A/lib/python3.5/site-packages/django/db/models/manager.py", line 82, in manager_method
    return getattr(self.get_queryset(), name)(*args, **kwargs)
  File "/home/ilkemirnurullah/.local/share/virtualenvs/Blog-0am4vL-A/lib/python3.5/site-packages/django/db/models/query.py", line 1136, in _insert
    return query.get_compiler(using=using).execute_sql(return_id)
  File "/home/ilkemirnurullah/.local/share/virtualenvs/Blog-0am4vL-A/lib/python3.5/site-packages/django/db/models/sql/compiler.py", line 1289, in execute_sql
    cursor.execute(sql, params)
  File "/home/ilkemirnurullah/.local/share/virtualenvs/Blog-0am4vL-A/lib/python3.5/site-packages/django/db/backends/utils.py", line 68, in execute
    return self._execute_with_wrappers(sql, params, many=False, executor=self._execute)
  File "/home/ilkemirnurullah/.local/share/virtualenvs/Blog-0am4vL-A/lib/python3.5/site-packages/django/db/backends/utils.py", line 77, in _execute_with_wrappers
    return executor(sql, params, many, context)
  File "/home/ilkemirnurullah/.local/share/virtualenvs/Blog-0am4vL-A/lib/python3.5/site-packages/django/db/backends/utils.py", line 85, in _execute
    return self.cursor.execute(sql, params)
  File "/home/ilkemirnurullah/.local/share/virtualenvs/Blog-0am4vL-A/lib/python3.5/site-packages/django/db/utils.py", line 89, in __exit__
    raise dj_exc_value.with_traceback(traceback) from exc_value
  File "/home/ilkemirnurullah/.local/share/virtualenvs/Blog-0am4vL-A/lib/python3.5/site-packages/django/db/backends/utils.py", line 85, in _execute
    return self.cursor.execute(sql, params)
django.db.utils.IntegrityError: null value in column "commentOfComment_id" violates not-null constraint
DETAIL:  Failing row contains (yorum cevabı, 2019-10-01 15:59:26.238312+00, null, 2, 3, 5).

[2019-10-01 22:04:49] ERROR Internal Server Error: /articles/commentOfcomment/3
Traceback (most recent call last):
  File "/home/ilkemirnurullah/.local/share/virtualenvs/Blog-0am4vL-A/lib/python3.5/site-packages/django/db/backends/utils.py", line 85, in _execute
    return self.cursor.execute(sql, params)
psycopg2.errors.NotNullViolation: null value in column "commentOfComment_id" violates not-null constraint
DETAIL:  Failing row contains (Cevap, 2019-10-01 19:04:49.769933+00, null, 2, 3, 5).


The above exception was the direct cause of the following exception:

Traceback (most recent call last):
  File "/home/ilkemirnurullah/.local/share/virtualenvs/Blog-0am4vL-A/lib/python3.5/site-packages/django/core/handlers/exception.py", line 34, in inner
    response = get_response(request)
  File "/home/ilkemirnurullah/.local/share/virtualenvs/Blog-0am4vL-A/lib/python3.5/site-packages/django/core/handlers/base.py", line 126, in _get_response
    response = self.process_exception_by_middleware(e, request)
  File "/home/ilkemirnurullah/.local/share/virtualenvs/Blog-0am4vL-A/lib/python3.5/site-packages/django/core/handlers/base.py", line 124, in _get_response
    response = wrapped_callback(request, *callback_args, **callback_kwargs)
  File "/home/ilkemirnurullah/.local/share/virtualenvs/Blog-0am4vL-A/lib/python3.5/site-packages/django/contrib/auth/decorators.py", line 21, in _wrapped_view
    return view_func(request, *args, **kwargs)
  File "/home/ilkemirnurullah/Blog/article/views.py", line 216, in addCommentofComment
    newCommentRe.save()
  File "/home/ilkemirnurullah/.local/share/virtualenvs/Blog-0am4vL-A/lib/python3.5/site-packages/django/db/models/base.py", line 718, in save
    force_update=force_update, update_fields=update_fields)
  File "/home/ilkemirnurullah/.local/share/virtualenvs/Blog-0am4vL-A/lib/python3.5/site-packages/django/db/models/base.py", line 748, in save_base
    updated = self._save_table(raw, cls, force_insert, force_update, using, update_fields)
  File "/home/ilkemirnurullah/.local/share/virtualenvs/Blog-0am4vL-A/lib/python3.5/site-packages/django/db/models/base.py", line 831, in _save_table
    result = self._do_insert(cls._base_manager, using, fields, update_pk, raw)
  File "/home/ilkemirnurullah/.local/share/virtualenvs/Blog-0am4vL-A/lib/python3.5/site-packages/django/db/models/base.py", line 869, in _do_insert
    using=using, raw=raw)
  File "/home/ilkemirnurullah/.local/share/virtualenvs/Blog-0am4vL-A/lib/python3.5/site-packages/django/db/models/manager.py", line 82, in manager_method
    return getattr(self.get_queryset(), name)(*args, **kwargs)
  File "/home/ilkemirnurullah/.local/share/virtualenvs/Blog-0am4vL-A/lib/python3.5/site-packages/django/db/models/query.py", line 1136, in _insert
    return query.get_compiler(using=using).execute_sql(return_id)
  File "/home/ilkemirnurullah/.local/share/virtualenvs/Blog-0am4vL-A/lib/python3.5/site-packages/django/db/models/sql/compiler.py", line 1289, in execute_sql
    cursor.execute(sql, params)
  File "/home/ilkemirnurullah/.local/share/virtualenvs/Blog-0am4vL-A/lib/python3.5/site-packages/django/db/backends/utils.py", line 68, in execute
    return self._execute_with_wrappers(sql, params, many=False, executor=self._execute)
  File "/home/ilkemirnurullah/.local/share/virtualenvs/Blog-0am4vL-A/lib/python3.5/site-packages/django/db/backends/utils.py", line 77, in _execute_with_wrappers
    return executor(sql, params, many, context)
  File "/home/ilkemirnurullah/.local/share/virtualenvs/Blog-0am4vL-A/lib/python3.5/site-packages/django/db/backends/utils.py", line 85, in _execute
    return self.cursor.execute(sql, params)
  File "/home/ilkemirnurullah/.local/share/virtualenvs/Blog-0am4vL-A/lib/python3.5/site-packages/django/db/utils.py", line 89, in __exit__
    raise dj_exc_value.with_traceback(traceback) from exc_value
  File "/home/ilkemirnurullah/.local/share/virtualenvs/Blog-0am4vL-A/lib/python3.5/site-packages/django/db/backends/utils.py", line 85, in _execute
    return self.cursor.execute(sql, params)
django.db.utils.IntegrityError: null value in column "commentOfComment_id" violates not-null constraint
DETAIL:  Failing row contains (Cevap, 2019-10-01 19:04:49.769933+00, null, 2, 3, 5).

